Traceback (most recent call last):
  File "C:\Users\miaha\anaconda3\lib\site-packages\jupyter_cache\executors\utils.py", line 51, in single_nb_execution
    executenb(
  File "C:\Users\miaha\anaconda3\lib\site-packages\nbclient\client.py", line 1112, in execute
    return NotebookClient(nb=nb, resources=resources, km=km, **kwargs).execute()
  File "C:\Users\miaha\anaconda3\lib\site-packages\nbclient\util.py", line 74, in wrapped
    return just_run(coro(*args, **kwargs))
  File "C:\Users\miaha\anaconda3\lib\site-packages\nbclient\util.py", line 53, in just_run
    return loop.run_until_complete(coro)
  File "C:\Users\miaha\anaconda3\lib\asyncio\base_events.py", line 642, in run_until_complete
    return future.result()
  File "C:\Users\miaha\anaconda3\lib\site-packages\nbclient\client.py", line 553, in async_execute
    await self.async_execute_cell(
  File "C:\Users\miaha\anaconda3\lib\site-packages\nbclient\client.py", line 857, in async_execute_cell
    self._check_raise_for_error(cell, exec_reply)
  File "C:\Users\miaha\anaconda3\lib\site-packages\nbclient\client.py", line 760, in _check_raise_for_error
    raise CellExecutionError.from_cell_and_msg(cell, exec_reply_content)
nbclient.exceptions.CellExecutionError: An error occurred while executing the following cell:
------------------
import pandas as pd
import numpy as np
import matplotlib.pyplot as plt
from matplotlib.pyplot import figure
import pickle
import os
from nltk import FreqDist
from PIL import Image
from nltk.corpus import PlaintextCorpusReader as pcr

from wordcloud import WordCloud
import community
from importlib import reload 
reload(community)


import gensim
import gensim.corpora as corpora
from gensim.models import CoherenceModel
from gensim.test.utils import common_corpus

import re
from vaderSentiment.vaderSentiment import SentimentIntensityAnalyzer
from IPython.display import Markdown as md

import warnings
warnings.filterwarnings("ignore")

%matplotlib inline 
------------------

[1;31m---------------------------------------------------------------------------[0m
[1;31mModuleNotFoundError[0m                       Traceback (most recent call last)
[1;32m~\AppData\Local\Temp/ipykernel_18964/966157166.py[0m in [0;36m<module>[1;34m[0m
[0;32m      9[0m [1;32mfrom[0m [0mnltk[0m[1;33m.[0m[0mcorpus[0m [1;32mimport[0m [0mPlaintextCorpusReader[0m [1;32mas[0m [0mpcr[0m[1;33m[0m[1;33m[0m[0m
[0;32m     10[0m [1;33m[0m[0m
[1;32m---> 11[1;33m [1;32mfrom[0m [0mwordcloud[0m [1;32mimport[0m [0mWordCloud[0m[1;33m[0m[1;33m[0m[0m
[0m[0;32m     12[0m [1;32mimport[0m [0mcommunity[0m[1;33m[0m[1;33m[0m[0m
[0;32m     13[0m [1;32mfrom[0m [0mimportlib[0m [1;32mimport[0m [0mreload[0m[1;33m[0m[1;33m[0m[0m

[1;31mModuleNotFoundError[0m: No module named 'wordcloud'
ModuleNotFoundError: No module named 'wordcloud'

